Workbook

Sheet Weather & Flight Plan
A1: Weather Log | G1: Date:
C2: Ceiling / Visibility / Precipitation | E2: Winds aloft | G2: Icing and Freezing level | H2: Turbulence and Cloud tops | I2: Position of fronts Low and highs
C3: Reported | D3: Forecast | E3: Speed | F3: Dir
A4: Departure
A5: En-route
A6: Destination
A7: Alternate
A9: Flight Plan
A10: Type of Flight | B10: Aircraft ID | C10: Aircraft Type / Equipment | D10: True Airspeed | E10: Departure Point | G10: Departure Time | I10: Cruising Altitude
G11: Estimated (UTC) | H11: Actual (UTC)
A12: VFR
A13: IFR
A14: Z / Y
A15: Route of flight
A17: Destination | D17: Estimated time en-route | G17: Remarks
D18: Hour | E18: Minutes
A20: Alternate Airport | D20: Fuel on Board | G20: Remarks
D21: Hour | E21: Minutes
A23: Notes / NOTAMs

Sheet Navigation Log
A1: Aircraft Number: | D1: ='Weather & Flight Plan'!B12 -> 0 | L1: TPA: | R1: GPH Rate: | U1: Enter your aircraft GPH
A2: RPM: | L2: Overfly: | R2: Start Fuel (gal): | U2: Enter your aircraft GPH
A3: Notes:
A4: Check Points | B4: VOR | D4: Course | E4: Altitude (MSL) | F4: Wind | H4: T A S | I4: TC | J4: TH | K4: MH | L4: C H | M4: Dis. | O4: GS | P4: Time | R4: GPH | S4: Departure | T4: ATIS | V4: Destination
B5: Freq. | F5: Dir | G5: Vel | I5: -L+R | J5: -E+W | K5: +/- | M5: Leg | N5: Rem. | P5: ETE | Q5: ETA
B6: Iden. | F6: Temp. | I6: WCA | J6: Var | K6: Dev | M6: Est. | N6: Est. | O6: Est. | P6: Est. | Q6: Est. | R6: Used
A7: =IFERROR('Weather & Flight Plan'!E12,"") -> 0 | M7: Act. | N7: Act. | O7: Act. | P7: Act. | Q7: Act. | R7: Rem.
F8: ='Weather & Flight Plan'!$F$4 -> 0 | G8: ='Weather & Flight Plan'!$E$4 -> 0 | J8: =D8+I9 -> #DIV/0! | K8: =J8+J9 -> #DIV/0! | L8: =MOD(K8+K9,360) -> #DIV/0! | M8: 0 | O8: =SQRT(H8^2+G8^2-(2*H8*G8*COS(RADIANS(I8-F8+I9)))) -> #DIV/0! | P8: =(M8/O8)*60 -> #DIV/0! | Q8: ='Weather & Flight Plan'!$G$12 -> 0 | R8: =(P8*1440/60)*$T$1 -> #DIV/0! | T8: ATIS Code
I9: =IF(A7="","",DEGREES(ASIN(($G$8*SIN(RADIANS($F$8-I8)))/H8))) -> #DIV/0! | Q9: ='Weather & Flight Plan'!$H$12 -> 0 | R9: =$T$2 -> 0
J10: =IF(A9="","",D10+I11) | K10: =IF(A9="","",J10+J11) | L10: =IF(A9="","",MOD(K10+K11,360)) | N10: =IF(A9="","",N8-M10) | O10: =IF(A9="","",SQRT(H10^2+G10^2-(2*H10*G10*COS(RADIANS(I10-F10+I11))))) | P10: =IF(A9="","",(M10/O10)*60) | Q10: =IF(A9="","",Q8+(P10/1440)) | R10: =IF(A9="","",(P10/60)*$T$1)
I11: =IF(A9="","",DEGREES(ASIN(($G$8*SIN(RADIANS($F$8-I10)))/H10))) | R11: =IF(A9="","",R9-R10)
J12: =IF(A11="","",D12+I13) | K12: =IF(A11="","",J12+J13) | L12: =IF(A11="","",MOD(K12+K13,360)) | N12: =IF(A11="","",N10-M12) | O12: =IF(A11="","",SQRT(H12^2+G12^2-(2*H12*G12*COS(RADIANS(I12-F12+I13))))) | P12: =IF(A11="","",(M12/O12)*60) | Q12: =IF(A11="","",Q10+(P12/1440)) | R12: =IF(A11="","",(P12/60)*$T$1) | S12: ='Weather & Flight Plan'!$C$4 -> 0 | T12: Ceiling / Visibility | V12: ='Weather & Flight Plan'!$C$6 -> 0
I13: =IF(A11="","",DEGREES(ASIN(($G$8*SIN(RADIANS($F$8-I12)))/H12))) | R13: =IF(A11="","",R11-R12)
J14: =IF(A13="","",D14+I15) | K14: =IF(A13="","",J14+J15) | L14: =IF(A13="","",MOD(K14+K15,360)) | N14: =IF(A13="","",N12-M14) | O14: =IF(A13="","",SQRT(H14^2+G14^2-(2*H14*G14*COS(RADIANS(I14-F14+I15))))) | P14: =IF(A13="","",(M14/O14)*60) | Q14: =IF(A13="","",Q12+(P14/1440)) | R14: =IF(A13="","",(P14/60)*$T$1)
I15: =IF(A13="","",DEGREES(ASIN(($G$8*SIN(RADIANS($F$8-I14)))/H14))) | R15: =IF(A13="","",R13-R14)
J16: =IF(A15="","",D16+I17) | K16: =IF(A15="","",J16+J17) | L16: =IF(A15="","",MOD(K16+K17,360)) | N16: =IF(A15="","",N14-M16) | O16: =IF(A15="","",SQRT(H16^2+G16^2-(2*H16*G16*COS(RADIANS(I16-F16+I17))))) | P16: =IF(A15="","",(M16/O16)*60) | Q16: =IF(A15="","",Q14+(P16/1440)) | R16: =IF(A15="","",(P16/60)*$T$1) | S16: ='Weather & Flight Plan'!$F$4 -> 0 | T16: Wind | V16: ='Weather & Flight Plan'!$F$6 -> 0
I17: =IF(A15="","",DEGREES(ASIN(($G$8*SIN(RADIANS($F$8-I16)))/H16))) | R17: =IF(A15="","",R15-R16)
J18: =IF(A17="","",D18+I19) | K18: =IF(A17="","",J18+J19) | L18: =IF(A17="","",MOD(K18+K19,360)) | N18: =IF(A17="","",N16-M18) | O18: =IF(A17="","",SQRT(H18^2+G18^2-(2*H18*G18*COS(RADIANS(I18-F18+I19))))) | P18: =IF(A17="","",(M18/O18)*60) | Q18: =IF(A17="","",Q16+(P18/1440)) | R18: =IF(A17="","",(P18/60)*$T$1)
I19: =IF(A17="","",DEGREES(ASIN(($G$8*SIN(RADIANS($F$8-I18)))/H18))) | R19: =IF(A17="","",R17-R18)
J20: =IF(A19="","",D20+I21) | K20: =IF(A19="","",J20+J21) | L20: =IF(A19="","",MOD(K20+K21,360)) | N20: =IF(A19="","",N18-M20) | O20: =IF(A19="","",SQRT(H20^2+G20^2-(2*H20*G20*COS(RADIANS(I20-F20+I21))))) | P20: =IF(A19="","",(M20/O20)*60) | Q20: =IF(A19="","",Q18+(P20/1440)) | R20: =IF(A19="","",(P20/60)*$T$1) | T20: Altimeter
I21: =IF(A19="","",DEGREES(ASIN(($G$8*SIN(RADIANS($F$8-I20)))/H20))) | R21: =IF(A19="","",R19-R20)
J22: =IF(A21="","",D22+I23) | K22: =IF(A21="","",J22+J23) | L22: =IF(A21="","",MOD(K22+K23,360)) | N22: =IF(A21="","",N20-M22) | O22: =IF(A21="","",SQRT(H22^2+G22^2-(2*H22*G22*COS(RADIANS(I22-F22+I23))))) | P22: =IF(A21="","",(M22/O22)*60) | Q22: =IF(A21="","",Q20+(P22/1440)) | R22: =IF(A21="","",(P22/60)*$T$1)
I23: =IF(A21="","",DEGREES(ASIN(($G$8*SIN(RADIANS($F$8-I22)))/H22))) | R23: =IF(A21="","",R21-R22)
J24: =IF(A23="","",D24+I25) | K24: =IF(A23="","",J24+J25) | L24: =IF(A23="","",MOD(K24+K25,360)) | N24: =IF(A23="","",N22-M24) | O24: =IF(A23="","",SQRT(H24^2+G24^2-(2*H24*G24*COS(RADIANS(I24-F24+I25))))) | P24: =IF(A23="","",(M24/O24)*60) | Q24: =IF(A23="","",Q22+(P24/1440)) | R24: =IF(A23="","",(P24/60)*$T$1) | T24: Apprch
I25: =IF(A23="","",DEGREES(ASIN(($G$8*SIN(RADIANS($F$8-I24)))/H24))) | R25: =IF(A23="","",R23-R24)
J26: =IF(A25="","",D26+I27) | K26: =IF(A25="","",J26+J27) | L26: =IF(A25="","",MOD(K26+K27,360)) | N26: =IF(A25="","",N24-M26) | O26: =IF(A25="","",SQRT(H26^2+G26^2-(2*H26*G26*COS(RADIANS(I26-F26+I27))))) | P26: =IF(A25="","",(M26/O26)*60) | Q26: =IF(A25="","",Q24+(P26/1440)) | R26: =IF(A25="","",(P26/60)*$T$1)
I27: =IF(A25="","",DEGREES(ASIN(($G$8*SIN(RADIANS($F$8-I26)))/H26))) | R27: =IF(A25="","",R25-R26)
J28: =IF(A27="","",D28+I29) | K28: =IF(A27="","",J28+J29) | L28: =IF(A27="","",MOD(K28+K29,360)) | N28: =IF(A27="","",N26-M28) | O28: =IF(A27="","",SQRT(H28^2+G28^2-(2*H28*G28*COS(RADIANS(I28-F28+I29))))) | P28: =IF(A27="","",(M28/O28)*60) | Q28: =IF(A27="","",Q26+(P28/1440)) | R28: =IF(A27="","",(P28/60)*$T$1) | T28: Runway
I29: =IF(A27="","",DEGREES(ASIN(($G$8*SIN(RADIANS($F$8-I28)))/H28))) | R29: =IF(A27="","",R27-R28)
J30: =IF(A29="","",D30+I31) | K30: =IF(A29="","",J30+J31) | L30: =IF(A29="","",MOD(K30+K31,360)) | N30: =IF(A29="","",N28-M30) | O30: =IF(A29="","",SQRT(H30^2+G30^2-(2*H30*G30*COS(RADIANS(I30-F30+I31))))) | P30: =IF(A29="","",(M30/O30)*60) | Q30: =IF(A29="","",Q28+(P30/1440)) | R30: =IF(A29="","",(P30/60)*$T$1)
I31: =IF(A29="","",DEGREES(ASIN(($G$8*SIN(RADIANS($F$8-I30)))/H30))) | R31: =IF(A29="","",R29-R30)
J32: =IF(A31="","",D32+I33) | K32: =IF(A31="","",J32+J33) | L32: =IF(A31="","",MOD(K32+K33,360)) | N32: =IF(A31="","",N30-M32) | O32: =IF(A31="","",SQRT(H32^2+G32^2-(2*H32*G32*COS(RADIANS(I32-F32+I33))))) | P32: =IF(A31="","",(M32/O32)*60) | Q32: =IF(A31="","",Q30+(P32/1440)) | R32: =IF(A31="","",(P32/60)*$T$1) | S32: Airport Frequencies
I33: =IF(A31="","",DEGREES(ASIN(($G$8*SIN(RADIANS($F$8-I32)))/H32))) | R33: =IF(A31="","",R31-R32) | S33: Departure | U33: Destination
J34: =IF(A33="","",D34+I35) | K34: =IF(A33="","",J34+J35) | L34: =IF(A33="","",MOD(K34+K35,360)) | N34: =IF(A33="","",N32-M34) | O34: =IF(A33="","",SQRT(H34^2+G34^2-(2*H34*G34*COS(RADIANS(I34-F34+I35))))) | P34: =IF(A33="","",(M34/O34)*60) | Q34: =IF(A33="","",Q32+(P34/1440)) | R34: =IF(A33="","",(P34/60)*$T$1) | S34: ATIS | U34: ATIS
I35: =IF(A33="","",DEGREES(ASIN(($G$8*SIN(RADIANS($F$8-I34)))/H34))) | R35: =IF(A33="","",R33-R34) | S35: Ground | U35: Apprch
J36: =IF(A35="","",D36+I37) | K36: =IF(A35="","",J36+J37) | L36: =IF(A35="","",MOD(K36+K37,360)) | N36: =IF(A35="","",N34-M36) | O36: =IF(A35="","",SQRT(H36^2+G36^2-(2*H36*G36*COS(RADIANS(I36-F36+I37))))) | P36: =IF(A35="","",(M36/O36)*60) | Q36: =IF(A35="","",Q34+(P36/1440)) | R36: =IF(A35="","",(P36/60)*$T$1) | S36: Tower | U36: Tower
I37: =IF(A35="","",DEGREES(ASIN(($G$8*SIN(RADIANS($F$8-I36)))/H36))) | R37: =IF(A35="","",R35-R36) | S37: Dep. | U37: Ground
J38: =IF(A37="","",D38+I39) | K38: =IF(A37="","",J38+J39) | L38: =IF(A37="","",MOD(K38+K39,360)) | N38: =IF(A37="","",N36-M38) | O38: =IF(A37="","",SQRT(H38^2+G38^2-(2*H38*G38*COS(RADIANS(I38-F38+I39))))) | P38: =IF(A37="","",(M38/O38)*60) | Q38: =IF(A37="","",Q36+(P38/1440)) | R38: =IF(A37="","",(P38/60)*$T$1) | S38: CTAF | U38: CTAF
I39: =IF(A37="","",DEGREES(ASIN(($G$8*SIN(RADIANS($F$8-I38)))/H38))) | R39: =IF(A37="","",R37-R38) | S39: FSS | U39: FSS
J40: =IF(A39="","",D40+I41) | K40: =IF(A39="","",J40+J41) | L40: =IF(A39="","",MOD(K40+K41,360)) | N40: =IF(A39="","",N38-M40) | O40: =IF(A39="","",SQRT(H40^2+G40^2-(2*H40*G40*COS(RADIANS(I40-F40+I41))))) | P40: =IF(A39="","",(M40/O40)*60) | Q40: =IF(A39="","",Q38+(P40/1440)) | R40: =IF(A39="","",(P40/60)*$T$1) | S40: Unicom | U40: Unicom
...

Sheet Weight & Balance
A1: WEIGHT & BALANCE
A2: Update blue cells for your specific aircraft. Verify all arms and limits in your aircraft POH.
A3: Aircraft Reference Data | B3: Value | C3: Units | D3: Notes
A4: Max Gross Weight | C4: lbs | D4: From your aircraft POH limitations section
A5: Max Usable Fuel | C5: gal | D5: Usable fuel only — check your POH
A6: Fuel Weight | C6: lbs/gal | D6: AvGas 100LL = 6.0 | Jet-A = 6.7 | MoGas = 6.1
A7: Empty Weight | C7: lbs | D7: From aircraft weight & balance records
A8: Empty Weight Arm | C8: in | D8: From aircraft weight & balance records
A9: Forward CG Limit | C9: in | D9: From POH CG envelope — check at your gross weight
A10: Aft CG Limit | C10: in | D10: From POH CG envelope — check at your gross weight
A12: Weight & Balance Calculation
A13: Item | B13: Weight (lbs) | C13: Arm (in) | D13: Moment (lb·in) | E13: Notes / Station
A14: Empty Aircraft | B14: =B7 -> 0 | C14: =B8 -> 0 | D14: =IFERROR(B14*C14,"") -> 0 | E14: From aircraft records (green = linked from above)
A15: Pilot (front left) | D15: =IFERROR(B15*C15,"") -> 0 | E15: Enter weight and arm from your POH station data
A16: Co-Pilot / Passenger (front right) | D16: =IFERROR(B16*C16,"") -> 0
A17: Rear Passenger (left) | D17: =IFERROR(B17*C17,"") -> 0
A18: Rear Passenger (right) | D18: =IFERROR(B18*C18,"") -> 0
A19: Baggage Area 1 | D19: =IFERROR(B19*C19,"") -> 0 | E19: Check max station weight limit in POH
A20: Baggage Area 2 | D20: =IFERROR(B20*C20,"") -> 0 | E20: Check max station weight limit in POH
A21: Fuel (usable) | B21: =B5*B6 -> 0 | D21: =IFERROR(B21*C21,"") -> 0 | E21: Enter fuel arm from POH — adjust weight for partial fuel
A22: TOTAL | B22: =SUM(B14,B15,B16,B17,B18,B19,B20,B21) -> 0 | D22: =SUM(D14,D15,D16,D17,D18,D19,D20,D21) -> 0
A23: CG Location (inches from datum) | D23: =IFERROR(D22/B22,"")
A24: Weight OK? (Max Gross) | D24: =IF(B22<=B4,"✓ WITHIN LIMITS ("&TEXT(B22,"0.0")&" / "&TEXT(B4,"0")&" lbs)","✗ OVER MAX GROSS WEIGHT") -> ✓ WITHIN LIMITS (0.0 / 0 lbs)
A25: CG OK? (Envelope) | D25: =IF(AND(D23>=B9,D23<=B10),"✓ CG IN ENVELOPE ("&TEXT(D23,"0.00")&" in)","✗ CG OUT OF ENVELOPE") -> ✓ CG IN ENVELOPE ( in)
A27: Notes

Sheet Fuel Required
A1: FUEL REQUIRED
A2: Blue = your inputs. Green = linked from other sheets. All calculations automatic.
A3: Flight Parameters (Inputs)
A4: Parameter | B4: Value | C4: Units | D4: Notes / Guidance
A5: GPH — Fuel Burn Rate | B5: ='Navigation Log'!T1 -> 0 | C5: gal/hr | D5: Linked from Nav Log — verify against your POH performance tables at cruise power
A6: Fuel On Board (available) | B6: ='Navigation Log'!T2 -> 0 | C6: gal | D6: Linked from Nav Log — usable fuel only, not total capacity
A7: TAS (for range calc) | C7: knots | D7: Enter your aircraft cruise TAS from POH
A8: Estimated Flight Time (ETE) | B8: =IFERROR('Weather & Flight Plan'!D19+('Weather & Flight Plan'!E19/60),"") -> 0 | C8: hrs | D8: Total ETE in decimal hours (e.g. 1.5 = 1 hr 30 min)
A9: Taxi & Run-up Time | C9: hrs | D9: ~15 min is standard — adjust as needed
A10: FAA Reserve Required | C10: hrs | D10: VFR day = 0.5 hrs (30 min) | VFR night / IFR = 0.75 hrs (45 min) | 14 CFR 91.151 / 91.167
A11: Alternate Airport Time | C11: hrs | D11: Required for IFR — add time en-route to alternate airport
A13: Fuel Calculations
A14: Item | B14: Fuel (gal) | C14: Time (hrs) | D14: Notes
A15: Trip Fuel | B15: =IFERROR(B8*B5,"") -> 0 | C15: =IFERROR(B8,"") -> 0 | D15: Flight time × GPH
A16: Taxi / Run-up Fuel | B16: =IFERROR(B9*B5,"") -> 0 | C16: =B9 -> 0 | D16: Taxi time × GPH
A17: Reserve Fuel (FAA minimum) | B17: =IFERROR(B10*B5,"") -> 0 | C17: =B10 -> 0 | D17: Reserve time × GPH | Per 14 CFR 91.151 / 91.167
A18: Alternate Airport Fuel | B18: =IFERROR(B11*B5,"") -> 0 | C18: =B11 -> 0 | D18: Alternate time × GPH (IFR only)
A19: TOTAL FUEL REQUIRED | B19: =SUM(B15,B16,B17,B18) -> 0 | C19: =SUM(C15,C16,C17,C18) -> 0 | D19: Trip + Taxi + Reserve + Alternate
A20: Fuel On Board | B20: =B6 -> 0 | C20: gal available
A21: Surplus / Deficit | B21: =IFERROR(B20-B19,"") -> 0 | C21: Positive = surplus. Negative = you need more fuel.
A22: Max Endurance | B22: =IFERROR(B6/B5,"") | C22: Full tanks at this burn rate (no reserve)
A23: Max Range (no reserve) | B23: =IFERROR(B22*B7,"") | C23: Endurance × TAS
A25: FUEL STATUS | D25: =IF(B21>=0,"✓ GO — Sufficient fuel on board ("&TEXT(B21,"0.0")&" gal surplus)","✗ NO-GO — Need "&TEXT(ABS(B21),"0.0")&" more gallons") -> ✓ GO — Sufficient fuel on board (0.0 gal surplus)
A27: Per-Leg Fuel Tracker
A28: Leg / Checkpoint | B28: ETE (min) | C28: GPH | D28: Est. Used (gal) | E28: Est. Rem. (gal) | F28: Act. Used | G28: Act. Rem. | H28: Notes
C29: =B5 -> 0 | D29: =IFERROR(IF(B29>0,B29/60*C29,""),"") | E29: =IFERROR(B6-D29,"")
C30: =B5 -> 0 | D30: =IFERROR(IF(B30>0,B30/60*C30,""),"") | E30: =IFERROR(E29-D30,"")
C31: =B5 -> 0 | D31: =IFERROR(IF(B31>0,B31/60*C31,""),"") | E31: =IFERROR(E30-D31,"")
C32: =B5 -> 0 | D32: =IFERROR(IF(B32>0,B32/60*C32,""),"") | E32: =IFERROR(E31-D32,"")
C33: =B5 -> 0 | D33: =IFERROR(IF(B33>0,B33/60*C33,""),"") | E33: =IFERROR(E32-D33,"")
C34: =B5 -> 0 | D34: =IFERROR(IF(B34>0,B34/60*C34,""),"") | E34: =IFERROR(E33-D34,"")
C35: =B5 -> 0 | D35: =IFERROR(IF(B35>0,B35/60*C35,""),"") | E35: =IFERROR(E34-D35,"")
C36: =B5 -> 0 | D36: =IFERROR(IF(B36>0,B36/60*C36,""),"") | E36: =IFERROR(E35-D36,"")
C37: =B5 -> 0 | D37: =IFERROR(IF(B37>0,B37/60*C37,""),"") | E37: =IFERROR(E36-D37,"")
C38: =B5 -> 0 | D38: =IFERROR(IF(B38>0,B38/60*C38,""),"") | E38: =IFERROR(E37-D38,"")

Sheet Performance
A1: PERFORMANCE
A2: Blue = your inputs. Green = calculated. POH lookup fields accept your pre-calculated values.
A3: Atmospheric Calculations
A4: Parameter | B4: Input Value | C4: Units | D4: Result | G4: Notes
A5: Field Elevation | C5: ft MSL | G5: From airport info / sectional
A6: Altimeter Setting | C6: inHg | G6: From ATIS / AWOS
A7: Outside Air Temp (OAT) | C7: °C | G7: From ATIS / thermometer
A8: Pressure Altitude | D8: =IFERROR(B5+(29.92-B6)*1000,"") -> 29920 | G8: Field Elev + (29.92 minus Altimeter) x 1000
A9: Density Altitude | D9: =IFERROR(D8+120*(B7-(15-2*D8/1000)),"") -> 35300.8 | G9: PA + 120 x (OAT minus ISA temp at PA)
A10: ISA Temp at Pressure Alt | D10: =IFERROR(15-2*D8/1000,"") -> -44.84 | G10: Standard atmosphere — compare to your OAT
A12: Wind Components
A13: Parameter | B13: Input Value | C13: Units | D13: Result | G13: Notes
A14: Runway Heading | C14: ° | G14: Magnetic heading of runway in use
A15: Wind Direction | C15: ° mag | G15: From ATIS — direction wind is FROM
A16: Wind Speed | C16: knots | G16: From ATIS
A17: Headwind Component | D17: =IFERROR(ROUND(B16*COS(RADIANS(B15-B14)),1),"") -> 0 | G17: Positive = headwind | Negative = tailwind
A18: Crosswind Component | D18: =IFERROR(ROUND(ABS(B16*SIN(RADIANS(B15-B14))),1),"") -> 0 | G18: Always positive — check your aircraft max demo crosswind
A20: V-Speed Reference (enter once from your POH)
A21: V-Speed | B21: KIAS | C21: Description | F21: Notes
A22: Vso | C22: Stall — landing config (flaps/gear down)
A23: Vs1 | C23: Stall — clean config
A24: Vr | C24: Rotation speed
A25: Vx | C25: Best angle of climb — obstacle clearance
A26: Vy | C26: Best rate of climb — altitude gain
A27: Va | C27: Maneuvering speed — max turbulence penetration
A28: Vfe | C28: Max flap extended speed
A29: Vno | C29: Max structural cruise speed
A30: Vne | C30: Never exceed speed
A32: Takeoff (from POH graphs at today's density altitude)
A33: Runway | D33: Ground Roll (ft) | E33: Surface | F33: Slope | G33: Obstacles / Notes
A37: Landing (from POH graphs at today's density altitude)
A38: Runway | D38: Ground Roll (ft) | E38: Surface | F38: Slope | G38: Obstacles / Notes
A42: Climb
A43: Item | B43: Value | C43: Units | D43: Notes
A44: Fly Vx (obstacle clearance) | C44: KIAS | D44: Link to your Vx above — use until clear of obstacles
A45: Fly Vy (best rate) | C45: KIAS | D45: Switch to Vy once clear — best altitude gain per minute
A46: Expected Climb Rate | C46: fpm | D46: From POH at today's density altitude — plan your time to cruise alt
A47: Time to Cruise Altitude | C47: min | D47: Calculate: (Cruise Alt − Field Elev) ÷ Climb Rate
A48: Fuel Used in Climb | C48: gal | D48: From POH climb table at density altitude
A50: Cruise
...

Sheet Preflight Checklist
A1: PREFLIGHT PLANNING CHECKLIST
A2: Complete before every flight. Green = GO | Yellow = review | Red = NO-GO
A3: IMSAFE — Personal Minimums
A4: Honestly assess each item. One NO is a NO-GO.
B5: I — Illness | E5: Am I free of any illness or symptoms affecting flight safety?
B6: M — Medication | E6: Am I free of any medication that could impair judgment or performance?
B7: S — Stress | E7: Am I free of significant psychological stress?
B8: A — Alcohol | E8: 8 hrs bottle to throttle. BAC below 0.04%. Last drink over 8 hrs ago?
B9: F — Fatigue | E9: Am I well rested and alert? Not fighting fatigue?
B10: E — Eating | E10: Am I properly hydrated and nourished for the flight?
A12: ARROW — Required Documents On Board
A13: All must be in the aircraft before departure.
B14: A — Airworthiness Certificate | E14: Original must be in aircraft — not a copy
B15: R — Registration | E15: Current — check expiry date
B16: R — Radio Station License | E16: Required for international flights
B17: O — Operating Handbook (POH) | E17: Current approved AFM/POH for this aircraft
B18: W — Weight & Balance | E18: Current W&B data — completed on this sheet
A20: Pilot Currency
B21: BFR — Biennial Flight Review | C21: Last date: | E21: Status: | F21: =IFERROR(IF(D21="","Enter date",IF(TODAY()-D21<=720,"✓ CURRENT","✗ EXPIRED")),"?") -> Enter date
B22: Last 3 Takeoffs & Landings (day passengers) | C22: Last date: | E22: Status: | F22: =IFERROR(IF(D22="","Enter date",IF(TODAY()-D22<=90,"✓ CURRENT","✗ EXPIRED")),"?") -> Enter date
B23: Last 3 Night T&Ls (night passengers) | C23: Last date: | E23: Status: | F23: =IFERROR(IF(D23="","Enter date",IF(TODAY()-D23<=90,"✓ CURRENT","✗ EXPIRED")),"?") -> Enter date
A25: Airspace & Routing
B26: TFR Check completed | E26: tfr.faa.gov — check entire route including departure and destination
B27: Special Use Airspace reviewed | E27: MOAs, Restricted, Prohibited areas along route — active times checked
B28: Charts current | E28: Sectional, TAC, IFR charts — check expiry date on chart margin
B29: Class B / C / D airspace along route | E29: Clearances / radio contact requirements noted on Nav Log
A31: Flight Plan
B32: Flight plan filed (VFR or IFR) | E32: 1800wxbrief.com or foreflight — include alternate if required
B33: Someone on the ground has your plan | E33: Name, route, destination, ETA — and what to do if not heard from
B34: Departure time noted / ETE calculated | E34: From Fuel Required and Nav Log sheets
A36: GO / NO-GO DECISION | C36: =IF(COUNTA($A$5,$A$6,$A$7,$A$8,$A$9,$A$10,$A$14,$A$15,$A$16,$A$17,$A$18,$A$21,$A$22,$A$23,$A$26,$A$27,$A$28,$A$29,$A$32,$A$33,$A$34)=21,"GO","NO-GO") -> NO-GO | E36: If in doubt, don't. The aircraft will be there tomorrow.

Sheet Pilot Log
A1: Date | B1: Aircraft (Make & Model) | C1: Aircraft Ident. | D1: Points of Departure & Arrival | F1: Aircraft Category | H1: Ground Trainer | I1: Type of Piloting Time | L1: Conditions of Flight | Q1: No. Instr. Appr. | R1: No. LDG. | T1: Total Duration of Flight | U1: Remarks, Procedures, Maneuvers
D2: From | E2: To | F2: Airplane SEL | G2: Airplane Mel | I2: Dual Recieved | J2: Pilot-in-Command | L2: Day | M2: Night | N2: Cross-Country | O2: Actual Instr. | P2: Simulated Instr. | R2: Day | S2: Night
A3: CURRENT FLIGHT (auto-filled) — Run LogFlight macro to commit to history below
A4: ='Weather & Flight Plan'!H1 -> 0 | B4: ='Weather & Flight Plan'!C12 -> 0 | C4: ='Weather & Flight Plan'!B12 -> 0 | D4: ='Weather & Flight Plan'!E12 -> 0 | E4: =IFERROR('Weather & Flight Plan'!A19,"") -> 0 | N4: =IFERROR(IF('Weather & Flight Plan'!E12<>'Weather & Flight Plan'!A19,F4,""),"") | T4: =IFERROR(INT('Navigation Log'!P42)&"h "&ROUND(('Navigation Log'!P42-INT('Navigation Log'!P42))*60,0)&"m","") -> 0h 0m
A5: FLIGHT HISTORY (rows added by LogFlight macro)

Sheet Macro Code
A1: LOGFLIGHT MACRO — OnlyOffice: View > Macros > New Macro > paste code > Run
A2: (function()
A3: {
A4: var oSheet = Api.GetActiveSheet();
A5: var pasteSheet = Api.GetSheet("Pilot Log");
A6: var STAGING_ROW = 3; // Row 4 = index 3 (0-based)
A7: var NUM_COLS = 21; // A to U
A9: // Find next empty row starting from index 5 (row 6)
A10: var lastRow = 5;
A11: while (pasteSheet.GetRangeByNumber(lastRow, 0, lastRow, 0).GetValue() !== "") {
A12: lastRow++;
A13: if (lastRow > 9999) break;
... A38: })();
